Workbook

Sheet Summary Ring
B1: Ring List After :
B2: No | C2: Prov | D2: Ring name | E2: Total Sites | F2: Type | G2: Total Distance(m) | H2: AVG / Site
B3: 1 | C3: =VLOOKUP(D3,'Lampiran Segment'!I:R,10,0) -> Banten | D3: Karangantu - Serang 1 | E3: =COUNTIFS('Lampiran Site'!R:R,'Summary Ring'!D3) -> 1 | F3: Star | G3: =SUMIFS('Lampiran Segment'!K:K,'Lampiran Segment'!I:I,'Summary Ring'!D3) -> 1751 | H3: =G3/E3 -> 1751
B4: 2 | C4: =VLOOKUP(D4,'Lampiran Segment'!I:R,10,0) -> Banten | D4: Rangkasbitung - Citeras | E4: =COUNTIFS('Lampiran Site'!R:R,'Summary Ring'!D4) -> 1 | F4: Star | G4: =SUMIFS('Lampiran Segment'!K:K,'Lampiran Segment'!I:I,'Summary Ring'!D4) -> 2085.6 | H4: =G4/E4 -> 2085.6
B5: 3 | C5: =VLOOKUP(D5,'Lampiran Segment'!I:R,10,0) -> Banten | D5: Citeras - Maja 1 | E5: =COUNTIFS('Lampiran Site'!R:R,'Summary Ring'!D5) -> 1 | F5: Star | G5: =SUMIFS('Lampiran Segment'!K:K,'Lampiran Segment'!I:I,'Summary Ring'!D5) -> 3128 | H5: =G5/E5 -> 3128
B6: 4 | C6: =VLOOKUP(D6,'Lampiran Segment'!I:R,10,0) -> Banten | D6: Jurangmangu - Pondok Ranji 1 | E6: =COUNTIFS('Lampiran Site'!R:R,'Summary Ring'!D6) -> 1 | F6: Star | G6: =SUMIFS('Lampiran Segment'!K:K,'Lampiran Segment'!I:I,'Summary Ring'!D6) -> 374 | H6: =G6/E6 -> 374
B7: 6 | C7: =VLOOKUP(D7,'Lampiran Segment'!I:R,10,0) -> JAWA BARAT | D7: Cirebon - Cirebon Perujakan 2 | E7: =COUNTIFS('Lampiran Site'!R:R,'Summary Ring'!D7) -> 1 | F7: Star | G7: =SUMIFS('Lampiran Segment'!K:K,'Lampiran Segment'!I:I,'Summary Ring'!D7) -> 452 | H7: =G7/E7 -> 452
B8: 7 | C8: =VLOOKUP(D8,'Lampiran Segment'!I:R,10,0) -> JAWA BARAT | D8: Cikampek - Pabuaran 1 | E8: =COUNTIFS('Lampiran Site'!R:R,'Summary Ring'!D8) -> 1 | F8: Star | G8: =SUMIFS('Lampiran Segment'!K:K,'Lampiran Segment'!I:I,'Summary Ring'!D8) -> 1889 | H8: =G8/E8 -> 1889
B9: 8 | C9: =VLOOKUP(D9,'Lampiran Segment'!I:R,10,0) -> JAWA BARAT | D9: Karangpucung - banjar 2 | E9: =COUNTIFS('Lampiran Site'!R:R,'Summary Ring'!D9) -> 1 | F9: Star | G9: =SUMIFS('Lampiran Segment'!K:K,'Lampiran Segment'!I:I,'Summary Ring'!D9) -> 657 | H9: =G9/E9 -> 657
B10: 9 | C10: =VLOOKUP(D10,'Lampiran Segment'!I:R,10,0) -> JAWA BARAT | D10: Wanaraja - Garut 3 | E10: =COUNTIFS('Lampiran Site'!R:R,'Summary Ring'!D10) -> 1 | F10: Star | G10: =SUMIFS('Lampiran Segment'!K:K,'Lampiran Segment'!I:I,'Summary Ring'!D10) -> 1312 | H10: =G10/E10 -> 1312
B11: 10 | C11: =VLOOKUP(D11,'Lampiran Segment'!I:R,10,0) -> JAWA BARAT | D11: Wanaraja - Garut 1 | E11: =COUNTIFS('Lampiran Site'!R:R,'Summary Ring'!D11) -> 1 | F11: Star | G11: =SUMIFS('Lampiran Segment'!K:K,'Lampiran Segment'!I:I,'Summary Ring'!D11) -> 119 | H11: =G11/E11 -> 119
B12: 11 | C12: =VLOOKUP(D12,'Lampiran Segment'!I:R,10,0) -> JAWA BARAT | D12: Haurpugur - Cicalengka 2 | E12: =COUNTIFS('Lampiran Site'!R:R,'Summary Ring'!D12) -> 1 | F12: Star | G12: =SUMIFS('Lampiran Segment'!K:K,'Lampiran Segment'!I:I,'Summary Ring'!D12) -> 1146 | H12: =G12/E12 -> 1146
B13: 12 | C13: =VLOOKUP(D13,'Lampiran Segment'!I:R,10,0) -> JAWA BARAT | D13: Rancaekek - Haurpugur 2 | E13: =COUNTIFS('Lampiran Site'!R:R,'Summary Ring'!D13) -> 1 | F13: Star | G13: =SUMIFS('Lampiran Segment'!K:K,'Lampiran Segment'!I:I,'Summary Ring'!D13) -> 1147 | H13: =G13/E13 -> 1147
B14: 13 | C14: =VLOOKUP(D14,'Lampiran Segment'!I:R,10,0) -> JAWA BARAT | D14: Cimekar - Rancaekek 1 | E14: =COUNTIFS('Lampiran Site'!R:R,'Summary Ring'!D14) -> 1 | F14: Star | G14: =SUMIFS('Lampiran Segment'!K:K,'Lampiran Segment'!I:I,'Summary Ring'!D14) -> 187 | H14: =G14/E14 -> 187
... B77: 99 | C77: =VLOOKUP(D77,'Lampiran Segment'!I:R,10,0) -> Jawa Timur | D77: BOWERNO - BABAT | E77: =COUNTIFS('Lampiran Site'!R:R,'Summary Ring'!D77) -> 1 | F77: Star | G77: =SUMIFS('Lampiran Segment'!K:K,'Lampiran Segment'!I:I,'Summary Ring'!D77) -> 913 | H77: =G77/E77 -> 913
D78: TOTAL | E78: =SUM(E3:E77) -> 77 | G78: =SUM(G3:G77) -> 87419.4 | H78: =G78/E78 -> 1135.3169

Sheet Lampiran Site
A2: Site List DRM :
A3: No | B3: Site_ID | C3: Site Name | D3: Site ID Surge | E3: Province | F3: City | G3: Kecamatan | H3: Kelurahan | I3: Lat | J3: Long | K3: Tower Ownership | L3: Field Type | M3: POP Interconnection | N3: Location POP | O3: Ketinggian Antenna | P3: Jumlah Sektor | Q3: FO Type | R3: Ring ID | S3: Distance/Site (m) | T3: Status Project
A4: 1 | B4: GTI12B046 | C4: Perkotaan | E4: BANTEN | F4: KOTA SERANG | G4: SERANG | H4: KOTA BARU | I4: -6.116444 | J4: 106.1515 | K4: GIHON | L4: GREEN FIELD | M4: Serang | N4: KAI | P4: 3 | Q4: Star | R4: Karangantu - Serang 1 | S4: =VLOOKUP(B4,'Lampiran Segment'!C1:K78,9,0) -> 1751 | T4: =VLOOKUP(B4,[1]List!$B$2:$AM$105,38,0) -> Go
A5: 2 | B5: T000365 | C5: CITERAS | E5: BANTEN | F5: KAB. LEBAK | G5: RANGKASBITUNG | H5: CITERAS | I5: -6.34117 | J5: 106.3231 | K5: TBG | L5: GREEN FIELD | M5: Rangkasbitung | N5: KAI | P5: 3 | Q5: Star | R5: Rangkasbitung - Citeras | S5: =VLOOKUP(B5,'Lampiran Segment'!C2:K79,9,0) -> 2085.6 | T5: =VLOOKUP(B5,[1]List!$B$2:$AM$105,38,0) -> Go
A6: 3 | B6: 130218104 | C6: MAJA | E6: BANTEN | F6: KAB. LEBAK | G6: MAJA | H6: MAJA | I6: -6.3423 | J6: 106.39772 | K6: TBG | L6: GREEN FIELD | M6: Maja | N6: KAI | P6: 3 | Q6: Star | R6: Citeras - Maja 1 | S6: =VLOOKUP(B6,'Lampiran Segment'!C3:K80,9,0) -> 3128 | T6: =VLOOKUP(B6,[1]List!$B$2:$AM$105,38,0) -> Go
A7: 4 | B7: 131098126 | C7: MCP PONDOK BETUNG 7 | E7: BANTEN | F7: KOTA TANGERANG SELATAN | G7: PONDOK AREN | H7: PONDOK BETUNG | I7: -6.27362 | J7: 106.74471 | K7: TBG | L7: GREEN FIELD | M7: Pondok Ranji | N7: KAI | P7: 3 | Q7: Star | R7: Jurangmangu - Pondok Ranji 1 | S7: =VLOOKUP(B7,'Lampiran Segment'!C4:K81,9,0) -> 374 | T7: =VLOOKUP(B7,[1]List!$B$2:$AM$105,38,0) -> Go
A8: 6 | B8: 121015104 | C8: PARUJAKAN | E8: JAWA BARAT | F8: KOTA CIREBON | G8: PEKALIPAN | H8: PEKALANGAN | I8: -6.71869 | J8: 108.55921 | K8: TBG | L8: GREEN FIELD | M8: Cirebon Prujakan | N8: KAI | P8: 3 | Q8: Star | R8: Cirebon - Cirebon Perujakan 2 | S8: =VLOOKUP(B8,'Lampiran Segment'!C6:K83,9,0) -> 452 | T8: =VLOOKUP(B8,[1]List!$B$2:$AM$105,38,0) -> Go
A9: 7 | B9: 122492110 | C9: PABUARAN BARAT | E9: JAWA BARAT | F9: KAB. SUBANG | G9: PABUARAN | H9: PABUARAN | I9: -6.41161 | J9: 107.57533 | K9: TBG | L9: GREEN FIELD | M9: Pabuaran | N9: KAI | P9: 3 | Q9: Star | R9: Cikampek - Pabuaran 1 | S9: =VLOOKUP(B9,'Lampiran Segment'!C7:K84,9,0) -> 1889 | T9: =VLOOKUP(B9,[1]List!$B$2:$AM$105,38,0) -> Go
A10: 8 | B10: 120851104 | C10: BANJAR | E10: JAWA BARAT | F10: KOTA BANJAR | G10: BANJAR | H10: MEKARSARI | I10: -7.37767 | J10: 108.5373 | K10: TBG | L10: GREEN FIELD | M10: Banjar | N10: KAI | P10: 3 | Q10: Star | R10: Karangpucung - banjar 2 | S10: =VLOOKUP(B10,'Lampiran Segment'!C8:K85,9,0) -> 657 | T10: =VLOOKUP(B10,[1]List!$B$2:$AM$105,38,0) -> Go
A11: 9 | B11: 120465109 | C11: SMP2TRNGKDL-SUCIKALER | E11: JAWA BARAT | F11: KAB. GARUT | G11: GARUT KOTA | H11: SUKAMENTRI | I11: -7.20741 | J11: 107.90977 | K11: TBG | L11: GREEN FIELD | M11: Garut | N11: KAI | P11: 3 | Q11: Star | R11: Wanaraja - Garut 3 | S11: =VLOOKUP(B11,'Lampiran Segment'!C9:K86,9,0) -> 1312 | T11: =VLOOKUP(B11,[1]List!$B$2:$AM$105,38,0) -> Go
A12: 10 | B12: 122876109 | C12: JL TELADAN GARUT | E12: JAWA BARAT | F12: KAB. GARUT | G12: GARUT KOTA | H12: PAKUWON | I12: -7.21398 | J12: 107.90526 | K12: TBG | L12: ROOF TOP | M12: Garut | N12: KAI | P12: 3 | Q12: Star | R12: Wanaraja - Garut 1 | S12: =VLOOKUP(B12,'Lampiran Segment'!C10:K87,9,0) -> 119 | T12: =VLOOKUP(B12,[1]List!$B$2:$AM$105,38,0) -> Go
A13: 11 | B13: 121272104 | C13: CICALENGKA | E13: JAWA BARAT | F13: KAB. BANDUNG | G13: CICALENGKA | H13: CIKUYA | I13: -6.98581 | J13: 107.83331 | K13: TBG | L13: GREEN FIELD | M13: Cicalengka | N13: KAI | P13: 3 | Q13: Star | R13: Haurpugur - Cicalengka 2 | S13: =VLOOKUP(B13,'Lampiran Segment'!C11:K88,9,0) -> 1146 | T13: =VLOOKUP(B13,[1]List!$B$2:$AM$105,38,0) -> Go
A14: 12 | B14: 121327104 | C14: HAURPUGUR | E14: JAWA BARAT | F14: KAB. BANDUNG | G14: RANCAEKEK | H14: HAURPUGUR | I14: -6.98902 | J14: 107.79942 | K14: TBG | L14: GREEN FIELD | M14: Haurpugur | N14: KAI | P14: 3 | Q14: Star | R14: Rancaekek - Haurpugur 2 | S14: =VLOOKUP(B14,'Lampiran Segment'!C11:K89,9,0) -> 1147 | T14: =VLOOKUP(B14,[1]List!$B$2:$AM$105,38,0) -> Go
A15: 13 | B15: 125871101 | C15: BDGN-218-WBBMC-SITE_7801 - RELOC | E15: JAWA BARAT | F15: KAB. BANDUNG | G15: RANCAEKEK | H15: RANCAEKEK KULON | I15: -6.96344 | J15: 107.75358 | K15: TBG | L15: GREEN FIELD | M15: Rancaekek | N15: KAI | P15: 3 | Q15: Star | R15: Cimekar - Rancaekek 1 | S15: =VLOOKUP(B15,'Lampiran Segment'!C12:K90,9,0) -> 187 | T15: =VLOOKUP(B15,[1]List!$B$2:$AM$105,38,0) -> Go
A16: 14 | B16: GTI25JBR023 | E16: JAWA BARAT | F16: KOTA BANDUNG | G16: CINAMBO | H16: BABAKAN PENGHULU | I16: -6.940518 | J16: 107.69118 | K16: GIHON | L16: ROOF TOP | M16: Gedebage | N16: KAI | P16: 3 | Q16: Star | R16: Kiaracondong - Gedebage 1 | S16: =VLOOKUP(B16,'Lampiran Segment'!C12:K91,9,0) -> 205 | T16: =VLOOKUP(B16,[1]List!$B$2:$AM$105,38,0) -> Go
A17: 15 | B17: 122376109 | C17: NGAMPRAH-BCAPDLARANG | E17: JAWA BARAT | F17: KAB. BANDUNG BARAT | G17: NGAMPRAH | H17: SUKATANI | I17: -6.83969 | J17: 107.49698 | K17: TBG | L17: GREEN FIELD | M17: Padalarang | N17: KAI | P17: 3 | Q17: Star | R17: Tagogapu - padalarang 1 | S17: =VLOOKUP(B17,'Lampiran Segment'!C13:K92,9,0) -> 815 | T17: =VLOOKUP(B17,[1]List!$B$2:$AM$105,38,0) -> Go
A18: 16 | B18: GTI13JB020 | C18: A Yani Purwamekar | E18: JAWA BARAT | F18: KAB. PURWAKARTA | G18: PURWAKARTA | H18: CIPAISAN | I18: -6.544083 | J18: 107.43622 | K18: GIHON | L18: GREEN FIELD | M18: Purwakarta | N18: KAI | P18: 3 | Q18: Star | R18: Sadang - Purwakarta 3 | S18: =VLOOKUP(B18,'Lampiran Segment'!C14:K93,9,0) -> 1934 | T18: =VLOOKUP(B18,[1]List!$B$2:$AM$105,38,0) -> Go
A19: 21 | B19: 125966123 | C19: SUKARAJA CILEBUT | E19: JAWA BARAT | F19: KAB. BOGOR | G19: SUKARAJA | H19: CILEBUT BARAT | I19: -6.52195 | J19: 106.79885 | K19: TBG | L19: GREEN FIELD | M19: Cilebut | N19: KAI | P19: 3 | Q19: Star | R19: Bojong Gede - Cilebut 1 | S19: =VLOOKUP(B19,'Lampiran Segment'!C18:K97,9,0) -> 963 | T19: =VLOOKUP(B19,[1]List!$B$2:$AM$105,38,0) -> Go
A20: 23 | B20: 1647052007 | C20: IBS MAKRO PEPELEGI | E20: JAWA TIMUR | F20: KAB. SIDOARJO | G20: GEDANGAN | H20: SAWOTRATAP | I20: -7.36763 | J20: 112.73315 | K20: TBG | L20: GREEN FIELD | M20: Sawotratap | N20: KAI | P20: 3 | Q20: Star | R20: WARU - SAWOTRATAP 2 | S20: =VLOOKUP(B20,'Lampiran Segment'!C20:K99,9,0) -> 606 | T20: =VLOOKUP(B20,[1]List!$B$2:$AM$105,38,0) -> Go
A21: 24 | B21: 161420110 | C21: GADING FAJAR | E21: JAWA TIMUR | F21: KAB. SIDOARJO | G21: BUDURAN | H21: SIWALANPANJI | I21: -7.43213 | J21: 112.72768 | K21: TBG | L21: GREEN FIELD | M21: Buduran | N21: KAI | P21: 3 | Q21: Star | R21: GEDANGAN - BUDURAN 3 | S21: =VLOOKUP(B21,'Lampiran Segment'!C21:K100,9,0) -> 1201 | T21: =VLOOKUP(B21,[1]List!$B$2:$AM$105,38,0) -> Go
A22: 25 | B22: 1649262007 | C22: IBS SUN CITY | E22: JAWA TIMUR | F22: KAB. SIDOARJO | G22: SIDOARJO | H22: SIDOKUMPUL | I22: -7.44911 | J22: 112.71009 | K22: TBG | L22: ROOF TOP | M22: Sidoarjo | N22: KAI | P22: 3 | Q22: Star | R22: PAGERWOJO - SIDOARJO 2 | S22: =VLOOKUP(B22,'Lampiran Segment'!C22:K101,9,0) -> 1226 | T22: =VLOOKUP(B22,[1]List!$B$2:$AM$105,38,0) -> Go
A23: 26 | B23: 1647062007 | C23: IBS KETAJEN | E23: JAWA TIMUR | F23: KAB. SIDOARJO | G23: GEDANGAN | H23: GEDANGAN | I23: -7.38745 | J23: 112.72716 | K23: TBG | L23: ROOF TOP | M23: Gedangan | N23: KAI | P23: 3 | Q23: Star | R23: SEPANJANG - GEDANGAN 1 | S23: =VLOOKUP(B23,'Lampiran Segment'!C23:K102,9,0) -> 520 | T23: =VLOOKUP(B23,[1]List!$B$2:$AM$105,38,0) -> Go
A24: 27 | B24: 163317126 | C24: JOMBATAN 2 | E24: JAWA TIMUR | F24: KAB. JOMBANG | G24: JOMBANG | H24: JOMBATAN | I24: -7.55253 | J24: 112.23177 | K24: TBG | L24: GREEN FIELD | M24: Jombang | N24: KAI | P24: 3 | Q24: Star | R24: PETERONGAN - JOMBANG 3 | S24: =VLOOKUP(B24,'Lampiran Segment'!C24:K103,9,0) -> 1891 | T24: =VLOOKUP(B24,[1]List!$B$2:$AM$105,38,0) -> Go
A25: 28 | B25: 161395110 | C25: 3G-BENTOEL OFFICE | E25: JAWA TIMUR | F25: KOTA MALANG | G25: KLOJEN | H25: KASIN | I25: -7.99556 | J25: 112.62598 | K25: TBG | L25: ROOF TOP | M25: Malang Kota Lama | N25: KAI | P25: 3 | Q25: Star | R25: PAKISAJI - MALANG KOTA LAMA 1 | S25: =VLOOKUP(B25,'Lampiran Segment'!C25:K104,9,0) -> 1721 | T25: =VLOOKUP(B25,[1]List!$B$2:$AM$105,38,0) -> Go
A26: 29 | B26: 1650662001 | C26: IBS MLG_INFILL7 | E26: JAWA TIMUR | F26: KOTA MALANG | G26: BLIMBING | H26: BLIMBING | I26: -7.94624 | J26: 112.64762 | K26: TBG | L26: GREEN FIELD | M26: Blimbing | N26: KAI | P26: 3 | Q26: Star | R26: MALANG - BLIMBING 1 | S26: =VLOOKUP(B26,'Lampiran Segment'!C26:K105,9,0) -> 997 | T26: =VLOOKUP(B26,[1]List!$B$2:$AM$105,38,0) -> Go
A27: 30 | B27: 163870110 | C27: KARANGLO - RELOC | E27: JAWA TIMUR | F27: KAB. MALANG | G27: SINGOSARI | H27: BANJARARUM | I27: -7.9042 | J27: 112.65996 | K27: TBG | L27: GREEN FIELD | M27: Singosari | N27: KAI | P27: 3 | Q27: Star | R27: BLIMBING - SINGOSARI 1 | S27: =VLOOKUP(B27,'Lampiran Segment'!C27:K106,9,0) -> 1332 | T27: =VLOOKUP(B27,[1]List!$B$2:$AM$105,38,0) -> Go
A28: 31 | B28: 1654591001 | C28: TEGAL GEDE 3 - RELOC | E28: JAWA TIMUR | F28: KAB. JEMBER | G28: KALIWATES | H28: KALIWATES | I28: -8.18112 | J28: 113.67416 | K28: TBG | L28: GREEN FIELD | M28: Kaliwates | N28: KAI | P28: 3 | Q28: Star | R28: MANGLI - KALIWATES 1 | S28: =VLOOKUP(B28,'Lampiran Segment'!C28:K107,9,0) -> 895 | T28: =VLOOKUP(B28,[1]List!$B$2:$AM$105,38,0) -> Go
A29: 32 | B29: 1510341001 | C29: GRAPHARI YOGYA RELOK | E29: DAERAH ISTIMEWA YOGYAKARTA | F29: KOTA YOGYAKARTA | G29: GONDOKUSUMAN | H29: TERBAN | I29: -7.78189 | J29: 110.37646 | K29: TBG | L29: GREEN FIELD | M29: LEMPUYANGAN | N29: KAI | P29: 3 | Q29: Star | R29: TUGU JOGJA - LEMPUYANGAN 4 | S29: =VLOOKUP(B29,'Lampiran Segment'!C28:K108,9,0) -> 1439 | T29: =VLOOKUP(B29,[1]List!$B$2:$AM$105,38,0) -> Go
A30: 35 | B30: 1472761003 | C30: GAJAHMADA TEGAL BARAT - RELOC | E30: JAWA TENGAH | F30: KOTA TEGAL | G30: TEGAL BARAT | H30: PEKAUMAN | I30: -6.87005 | J30: 109.12783 | K30: TBG | L30: RT | M30: Tegal | N30: KAI | P30: 3 | Q30: Star | R30: Brebes - Tegal 1 | S30: =VLOOKUP(B30,'Lampiran Segment'!C29:K111,9,0) -> 2194.8 | T30: =VLOOKUP(B30,[1]List!$AO$2:$BD$105,16,0) -> Go
A31: 36 | B31: 1440632003 | C31: IBS TUGU REJO | E31: JAWA TENGAH | F31: KOTA SEMARANG | G31: TUGU | H31: TUGUREJO | I31: -6.9838 | J31: 110.35695 | K31: TBG | L31: GREEN FIELD | M31: Jerakah | N31: KAI | P31: 3 | Q31: Star | R31: Mangkang - Jerakah 1 | S31: =VLOOKUP(B31,'Lampiran Segment'!C30:K112,9,0) -> 1869 | T31: =VLOOKUP(B31,[1]List!$B$2:$AM$105,38,0) -> Go
A32: 38 | B32: TBG03_CJ007 | C32: BANDAR HARJO | E32: JAWA TENGAH | F32: KOTA SEMARANG | G32: SEMARANG UTARA | H32: BANDARHARJO | I32: -6.96498 | J32: 110.42412 | K32: TBG | L32: GREEN FIELD | M32: Semarang Tawang | N32: KAI | P32: 3 | Q32: Star | R32: Semarang Poncol - Semarang Tawang 3 | S32: =VLOOKUP(B32,'Lampiran Segment'!C31:K114,9,0) -> 317 | T32: =VLOOKUP(B32,[1]List!$B$2:$AM$105,38,0) -> Go
A33: 39 | B33: 111172121 | C33: GATEP SAWAH MC-T-GF | E33: DKI JAKARTA | F33: KOTA ADM. JAKARTA PUSAT | G33: SAWAH BESAR | H33: MANGGA DUA SELATAN | I33: -6.14037 | J33: 106.82288 | K33: TBG | L33: GREEN FIELD | M33: Jayakarta | N33: KAI | P33: 3 | Q33: Star | R33: Angke - Jayakarta A | S33: =VLOOKUP(B33,'Lampiran Segment'!C32:K115,9,0) -> 396 | T33: =VLOOKUP(B33,[1]List!$B$2:$AM$105,38,0) -> Go
A34: 40 | B34: 1133122004 | C34: IBS LOKASARI PLAZA | E34: DKI JAKARTA | F34: KOTA ADM. JAKARTA BARAT | G34: TAMAN SARI | H34: TANGKI | I34: -6.14633 | J34: 106.82336 | K34: TBG | L34: ROOF TOP | M34: Jayakarta | N34: KAI | P34: 3 | Q34: Star | R34: Angke - Jayakarta B | S34: =VLOOKUP(B34,'Lampiran Segment'!C33:K116,9,0) -> 1507 | T34: =VLOOKUP(B34,[1]List!$B$2:$AM$105,38,0) -> Go
A35: 42 | B35: 1133112004 | C35: IBS RUMAH KOST/CV TAMAN SARI | E35: DKI JAKARTA | F35: KOTA ADM. JAKARTA BARAT | G35: TAMAN SARI | H35: TAMAN SARI | I35: -6.15238 | J35: 106.8238 | K35: TBG | L35: ROOF TOP | M35: Mangga Besar | N35: KAI | P35: 3 | Q35: Star | R35: Duri - Mangga Besar | S35: =VLOOKUP(B35,'Lampiran Segment'!C34:K118,9,0) -> 903 | T35: =VLOOKUP(B35,[1]List!$B$2:$AM$105,38,0) -> Go
A36: 43 | B36: 111545109 | C36: BATIK HAJADI | E36: DKI JAKARTA | F36: KOTA ADM. JAKARTA PUSAT | G36: TANAH ABANG | H36: GELORA | I36: -6.20307 | J36: 106.79791 | K36: TBG | L36: GREEN FIELD | M36: Palmerah | N36: KAI | P36: 3 | Q36: Star | R36: Tanah Abang - Palmerah | S36: =VLOOKUP(B36,'Lampiran Segment'!C34:K119,9,0) -> 963 | T36: =VLOOKUP(B36,[1]List!$B$2:$AM$105,38,0) -> Go
A37: 50 | B37: 111211121 | C37: PENGHULU LAMA MC-T-GF | E37: DKI JAKARTA | F37: KOTA ADM. JAKARTA SELATAN | G37: KEBAYORAN LAMA | H37: KEBAYORAN LAMA UTARA | I37: -6.2408 | J37: 106.78107 | K37: TBG | L37: GREEN FIELD | M37: Kebayoran | N37: KAI | P37: 3 | Q37: Star | R37: Kebayoran - Pondok Ranji | S37: =VLOOKUP(B37,'Lampiran Segment'!C41:K126,9,0) -> 81 | T37: =VLOOKUP(B37,[1]List!$B$2:$AM$105,38,0) -> Go
A38: 51 | B38: GTI11B012 | C38: Station Cilegon | E38: BANTEN | F38: KOTA CILEGON | G38: JOMBANG | H38: JOMBANG WETAN | I38: -6.017389 | J38: 106.0525 | K38: GIHON | L38: ROOF TOP | M38: Cilegon | N38: KAI | P38: 3 | Q38: Star | R38: Krenceng - Cilegon 1 | S38: =VLOOKUP(B38,'Lampiran Segment'!F1:K78,6,0) -> 736 | T38: =VLOOKUP(B38,[1]List!$B$2:$AM$105,38,0) -> Go
A39: 52 | B39: 1321162007 | C39: IBS CIMUNCANG SERANG | E39: BANTEN | F39: KOTA SERANG | G39: SERANG | H39: CIMUNCANG | I39: -6.11636 | J39: 106.162 | K39: TBG | L39: GREEN FIELD | M39: Serang | N39: KAI | P39: 3 | Q39: Star | R39: Karangantu - Serang 2 | S39: =VLOOKUP(B39,'Lampiran Segment'!F2:K79,6,0) -> 445 | T39: =VLOOKUP(B39,[1]List!$B$2:$AM$105,38,0) -> Go
A40: 53 | B40: 130176110 | C40: 3G ABDUL HADI PANDEGLANG | E40: BANTEN | F40: KOTA SERANG | G40: SERANG | H40: CIPARE | I40: -6.12559 | J40: 106.15986 | K40: TBG | L40: ROOF TOP | M40: Serang | N40: KAI | P40: 3 | Q40: Star | R40: Serang - Walantaka 1 | S40: =VLOOKUP(B40,'Lampiran Segment'!F3:K80,6,0) -> 1891 | T40: =VLOOKUP(B40,[1]List!$B$2:$AM$105,38,0) -> Go
A41: 54 | B41: 1323011003 | C41: CIKANDE_CEMPLANG | E41: BANTEN | F41: KAB. SERANG | G41: JAWILAN | H41: CEMPLANG | I41: -6.329 | J41: 106.33747 | K41: TBG | L41: GREEN FIELD | M41: Citeras | N41: KAI | P41: 3 | Q41: Star | R41: Citeras - Maja 2 | S41: =VLOOKUP(B41,'Lampiran Segment'!F4:K81,6,0) -> 1370 | T41: =VLOOKUP(B41,[1]List!$B$2:$AM$105,38,0) -> Go
...

Sheet Lampiran Segment
A1: NO | B1: Segment | C1: NE | D1: NE Long | E1: NE Lat | F1: FE | G1: FE Long | H1: FE Lat | I1: ring_name | J1: route_type | K1: length | L1: FO Hub 1 | M1: FO Hub 2 | N1: POP Type | O1: status site a | P1: status site b | Q1: RFS Plan | R1: Provinsi | S1: Kota Kab | T1: Vendor | U1: Status
A2: 1 | B2: Cilegon;GTI11B012 | C2: Cilegon | D2: 106.05512 | E2: -6.020456 | F2: GTI11B012 | G2: 106.0525 | H2: -6.017389 | I2: Krenceng - Cilegon 1 | J2: Star | K2: 736 | L2: Krenceng | M2: Cilegon 1 | N2: KAI | O2: Station | P2: Direct to Station | R2: Banten | S2: KOTA CILEGON | U2: =VLOOKUP(F2,'Lampiran Site'!$B$3:$T$80,19,0) -> Go | V2: =VLOOKUP(C2,'Lampiran Site'!$B$3:$B$80,1,0) -> #N/A
A3: 2 | B3: GTI12B046;Serang | C3: GTI12B046 | D3: 106.1515 | E3: -6.116444 | F3: Serang | G3: 106.1599 | H3: -6.11546 | I3: Karangantu - Serang 1 | J3: Star | K3: 1751 | L3: Karangantu | M3: Serang 1 | N3: KAI | O3: Direct to Station | P3: Sation | R3: Banten | S3: KOTA SERANG | U3: =VLOOKUP(C3,'Lampiran Site'!$B$3:$T$80,19,0) -> Go
A4: 3 | B4: Serang;1321162007 | C4: Serang | D4: 106.1599 | E4: -6.11546 | F4: 1321162007 | G4: 106.162 | H4: -6.11636 | I4: Karangantu - Serang 2 | J4: Star | K4: 445 | L4: Karangantu | M4: Serang 2 | N4: KAI | O4: Station | P4: Direct to Station | R4: Banten | S4: KOTA SERANG | U4: =VLOOKUP(F4,'Lampiran Site'!$B$3:$T$80,19,0) -> Go
A5: 4 | B5: Serang;130176110 | C5: Serang | D5: 106.1599 | E5: -6.11546 | F5: 130176110 | G5: 106.15986 | H5: -6.12559 | I5: Serang - Walantaka 1 | J5: Star | K5: 1891 | L5: Serang | M5: Walantaka 1 | N5: KAI | O5: Station | P5: Direct to Station | R5: Banten | S5: KOTA SERANG | U5: =VLOOKUP(F5,'Lampiran Site'!$B$3:$T$80,19,0) -> Go
A6: 5 | B6: T000365;Rangkasbitung; | C6: T000365 | D6: 106.3231 | E6: -6.34117 | F6: Rangkasbitung | G6: 106.2515 | H6: -6.352713 | I6: Rangkasbitung - Citeras | J6: Star | K6: 2085.6 | L6: Rangkasbitung | M6: Citeras | N6: KAI | O6: Direct to Station | P6: Sation | R6: Banten | S6: KAB. LEBAK | U6: =VLOOKUP(C6,'Lampiran Site'!$B$3:$T$80,19,0) -> Go
A7: 6 | B7: 130218104;Maja | C7: 130218104 | D7: 106.39772 | E7: -6.3423 | F7: Maja | G7: 106.39449 | H7: -6.331748 | I7: Citeras - Maja 1 | J7: Star | K7: 3128 | L7: Citeras | M7: Maja 1 | N7: KAI | O7: Direct to Station | P7: Sation | R7: Banten | S7: KAB. LEBAK | U7: =VLOOKUP(C7,'Lampiran Site'!$B$3:$T$80,19,0) -> Go
A8: 7 | B8: Citeras;1323011003 | C8: Citeras | D8: 106.33108 | E8: -6.335325 | F8: 1323011003 | G8: 106.33747 | H8: -6.329 | I8: Citeras - Maja 2 | J8: Star | K8: 1370 | L8: Citeras | M8: Maja 2 | N8: KAI | O8: Station | P8: Direct to Station | R8: Banten | S8: KAB. SERANG | U8: =VLOOKUP(F8,'Lampiran Site'!$B$3:$T$80,19,0) -> Go
A9: 8 | B9: Rawa Buntu;GTI13B023 | C9: Rawa Buntu | D9: 106.67723 | E9: -6.314366 | F9: GTI13B023 | G9: 106.68326 | H9: -6.30754 | I9: Rawa Buntu - Sudimara 4 | J9: Star | K9: 1567 | L9: Rawa Buntu | M9: Sudimara 4 | N9: KAI | O9: Station | P9: Direct to Station | R9: Banten | S9: KOTA TANGERANG SELATAN | U9: =VLOOKUP(F9,'Lampiran Site'!$B$3:$T$80,19,0) -> Go
A10: 9 | B10: Sudimara;1303981004 | C10: Sudimara | D10: 106.7113 | E10: -6.297691 | F10: 1303981004 | G10: 106.71478 | H10: -6.29581 | I10: Sudimara - Jurangmangu 1 | J10: Star | K10: 810 | L10: Sudimara | M10: Jurangmangu 1 | N10: KAI | O10: Station | P10: Direct to Station | R10: Banten | S10: KOTA TANGERANG SELATAN | U10: =VLOOKUP(F10,'Lampiran Site'!$B$3:$T$80,19,0) -> Go
A11: 11 | B11: 131098126;Pondok Ranji | C11: 131098126 | D11: 106.74471 | E11: -6.27362 | F11: Pondok Ranji | G11: 106.74549 | H11: -6.275998 | I11: Jurangmangu - Pondok Ranji 1 | J11: Star | K11: 374 | L11: Jurangmangu | M11: Pondok Ranji 1 | N11: KAI | O11: Direct to Station | P11: Sation | R11: Banten | S11: KOTA TANGERANG SELATAN | U11: =VLOOKUP(C11,'Lampiran Site'!$B$3:$T$80,19,0) -> Go
A12: 13 | B12: 121015104;Cirebon Prujakan | C12: 121015104 | D12: -6.71869 | E12: 108.559 | F12: Cirebon Prujakan | G12: 108.5588 | H12: -6.719353 | I12: Cirebon - Cirebon Perujakan 2 | J12: Star | K12: 452 | L12: Cirebon | M12: Cirebon Perujakan 2 | N12: KAI | O12: Direct to Station | P12: Sation | R12: JAWA BARAT | S12: KOTA CIREBON | U12: =VLOOKUP(C12,'Lampiran Site'!$B$3:$T$80,19,0) -> Go
A13: 14 | B13: 122492110;Pabuaran | C13: 122492110 | D13: -6.41161 | E13: 107.575 | F13: Pabuaran | G13: 107.58406 | H13: -6.409285 | I13: Cikampek - Pabuaran 1 | J13: Star | K13: 1889 | L13: Cikampek | M13: Pabuaran 1 | N13: KAI | O13: Direct to Station | P13: Sation | R13: JAWA BARAT | S13: KAB. SUBANG | U13: =VLOOKUP(C13,'Lampiran Site'!$B$3:$T$80,19,0) -> Go
A14: 15 | B14: Banjar;122861109 | C14: Banjar | D14: 108.54244 | E14: -7.376347 | F14: 122861109 | G14: -7.38018 | H14: 108.543 | I14: Banjar - Langen 1 | J14: Star | K14: 802 | L14: Banjar | M14: Langen 1 | N14: KAI | O14: Station | P14: Direct to Station | R14: JAWA BARAT | S14: KOTA BANJAR | U14: =VLOOKUP(F14,'Lampiran Site'!$B$3:$T$80,19,0) -> Go
A15: 16 | B15: 120851104;Banjar | C15: 120851104 | D15: -7.37767 | E15: 108.537 | F15: Banjar | G15: 108.54244 | H15: -7.376347 | I15: Karangpucung - banjar 2 | J15: Star | K15: 657 | L15: Karangpucung | M15: banjar 2 | N15: KAI | O15: Direct to Station | P15: Sation | R15: JAWA BARAT | S15: KOTA BANJAR | U15: =VLOOKUP(C15,'Lampiran Site'!$B$3:$T$80,19,0) -> Go
A16: 17 | B16: Leuwigoong;121075104 | C16: Leuwigoong | D16: 107.95828 | E16: -7.103436 | F16: 121075104 | G16: -7.09941 | H16: 107.958 | I16: Leuwigoong - Cibatu 1 | J16: Star | K16: 664 | L16: Leuwigoong | M16: Cibatu 1 | N16: KAI | O16: Station | P16: Direct to Station | R16: JAWA BARAT | S16: KAB. GARUT | U16: =VLOOKUP(F16,'Lampiran Site'!$B$3:$T$80,19,0) -> Go
A17: 18 | B17: 120465109;Garut | C17: 120465109 | D17: -7.20741 | E17: 107.91 | F17: Garut | G17: 107.90358 | H17: -7.213519 | I17: Wanaraja - Garut 3 | J17: Star | K17: 1312 | L17: Wanaraja | M17: Garut 3 | N17: KAI | O17: Direct to Station | P17: Sation | R17: JAWA BARAT | S17: KAB. GARUT | U17: =VLOOKUP(C17,'Lampiran Site'!$B$3:$T$80,19,0) -> Go
A18: 19 | B18: 122876109;Garut | C18: 122876109 | D18: -7.21398 | E18: 107.905 | F18: Garut | G18: 107.90358 | H18: -7.213519 | I18: Wanaraja - Garut 1 | J18: Star | K18: 119 | L18: Wanaraja | M18: Garut 1 | N18: KAI | O18: Direct to Station | P18: Sation | R18: JAWA BARAT | S18: KAB. GARUT | U18: =VLOOKUP(C18,'Lampiran Site'!$B$3:$T$80,19,0) -> Go
A19: 20 | B19: 121272104;Cicalengka | C19: 121272104 | D19: -6.98581 | E19: 107.833 | F19: Cicalengka | G19: 107.83283 | H19: -6.981614 | I19: Haurpugur - Cicalengka 2 | J19: Star | K19: 1146 | L19: Haurpugur | M19: Cicalengka 2 | N19: KAI | O19: Direct to Station | P19: Sation | R19: JAWA BARAT | S19: KAB. BANDUNG | U19: =VLOOKUP(C19,'Lampiran Site'!$B$3:$T$80,19,0) -> Go
A20: 21 | B20: 121327104;Haurpugur | C20: 121327104 | D20: -6.98902 | E20: 107.799 | F20: Haurpugur | G20: 107.79987 | H20: -6.98075 | I20: Rancaekek - Haurpugur 2 | J20: Star | K20: 1147 | L20: Rancaekek | M20: Haurpugur 2 | N20: KAI | O20: Direct to Station | P20: Sation | R20: JAWA BARAT | S20: KAB. BANDUNG | U20: =VLOOKUP(C20,'Lampiran Site'!$B$3:$T$80,19,0) -> Go
A21: 22 | B21: Rancaekek;124714126 | C21: Rancaekek | D21: 107.75575 | E21: -6.964729 | F21: 124714126 | G21: -6.95981 | H21: 107.761 | I21: Rancaekek - Haurpugur 1 | J21: Star | K21: 1415 | L21: Rancaekek | M21: Haurpugur 1 | N21: KAI | O21: Station | P21: Direct to Station | R21: JAWA BARAT | S21: KAB. BANDUNG | U21: =VLOOKUP(F21,'Lampiran Site'!$B$3:$T$80,19,0) -> Go
A22: 23 | B22: 125871101;Rancaekek | C22: 125871101 | D22: -6.96344 | E22: 107.754 | F22: Rancaekek | G22: 107.75575 | H22: -6.964729 | I22: Cimekar - Rancaekek 1 | J22: Star | K22: 187 | L22: Cimekar | M22: Rancaekek 1 | N22: KAI | O22: Direct to Station | P22: Sation | R22: JAWA BARAT | S22: KAB. BANDUNG | U22: =VLOOKUP(C22,'Lampiran Site'!$B$3:$T$80,19,0) -> Go
A23: 24 | B23: Kiaracondong;125841103 | C23: Kiaracondong | D23: 107.64623 | E23: -6.925123 | F23: 125841103 | G23: -6.92417 | H23: 107.649 | I23: Kiaracondong - Gedebage 1 | J23: Star | K23: 859 | L23: Kiaracondong | M23: Gedebage 1 | N23: KAI | O23: Station | P23: Direct to Station | R23: JAWA BARAT | S23: KOTA BANDUNG | U23: =VLOOKUP(F23,'Lampiran Site'!$B$3:$T$80,19,0) -> Go
A24: 25 | B24: GTI25JBR023;Gedebage | C24: GTI25JBR023 | D24: -6.94052 | E24: 107.691 | F24: Gedebage | G24: 107.68944 | H24: -6.94096 | I24: Kiaracondong - Gedebage 1 | J24: Star | K24: 205 | L24: Kiaracondong | M24: Gedebage 1 | N24: KAI | O24: Direct to Station | P24: Sation | R24: JAWA BARAT | S24: KOTA BANDUNG | U24: =VLOOKUP(C24,'Lampiran Site'!$B$3:$T$80,19,0) -> Go
A25: 26 | B25: 122376109;Padalarang | C25: 122376109 | D25: -6.83969 | E25: 107.497 | F25: Padalarang | G25: 107.49734 | H25: -6.843111 | I25: Tagogapu - padalarang 1 | J25: Star | K25: 815 | L25: Tagogapu | M25: padalarang 1 | N25: KAI | O25: Direct to Station | P25: Sation | R25: JAWA BARAT | S25: KAB. BANDUNG BARAT | U25: =VLOOKUP(C25,'Lampiran Site'!$B$3:$T$80,19,0) -> Go
A26: 27 | B26: GTI13JB020;Purwakarta | C26: GTI13JB020 | D26: -6.54408 | E26: 107.436 | F26: Purwakarta | G26: 107.44621 | H26: -6.552578 | I26: Sadang - Purwakarta 3 | J26: Star | K26: 1934 | L26: Sadang | M26: Purwakarta 3 | N26: KAI | O26: Direct to Station | P26: Sation | R26: JAWA BARAT | S26: KAB. PURWAKARTA | U26: =VLOOKUP(C26,'Lampiran Site'!$B$3:$T$80,19,0) -> Go
A27: 29 | B27: 123556109;GTI12JB015 | C27: 123556109 | D27: -6.25807 | E27: 107.058 | F27: GTI12JB015 | G27: -6.25739 | H27: 107.062 | I27: Tambun - Cibitung 2 | J27: Star | K27: 1115 | L27: Tambun | M27: Cibitung 2 | N27: KAI | O27: Station | P27: Direct to Station | R27: JAWA BARAT | S27: KAB. BEKASI | U27: =VLOOKUP(F27,'Lampiran Site'!$B$3:$T$80,19,0) -> Go
A28: 33 | B28: 125966123;Cilebut | C28: 125966123 | D28: -6.52195 | E28: 106.799 | F28: Cilebut | G28: 106.80057 | H28: -6.530491 | I28: Bojong Gede - Cilebut 1 | J28: Star | K28: 963 | L28: Bojong Gede | M28: Cilebut 1 | N28: KAI | O28: Direct to Station | P28: Sation | R28: JAWA BARAT | S28: KAB. BOGOR | U28: =VLOOKUP(C28,'Lampiran Site'!$B$3:$T$80,19,0) -> Go
A29: 34 | B29: Bojong Gede;120288109 | C29: Bojong Gede | D29: 106.79487 | E29: -6.493185 | F29: 120288109 | G29: -6.49693 | H29: 106.8 | I29: Bojong Gede - Cibinong | J29: Star | K29: 786 | L29: Bojong Gede | M29: Cibinong | N29: KAI | O29: Station | P29: Direct to Station | R29: JAWA BARAT | S29: KAB. BOGOR | U29: =VLOOKUP(F29,'Lampiran Site'!$B$3:$T$80,19,0) -> Go
A30: 36 | B30: Surabaya Pasar Turi;T000043 | C30: Surabaya Pasar Turi | D30: -7.245962 | E30: 112.73263 | F30: T000043 | G30: -7.24665 | H30: 112.73391 | I30: SURABAYA PASAR TURI - SURABAYA KOTA 3 | J30: Star | K30: 257 | L30: SURABAYA PASAR TURI | M30: SURABAYA KOTA 3 | N30: KAI | O30: Station | P30: Direct to Station | R30: Jawa Timur | S30: KOTA SURABAYA | U30: =VLOOKUP(F30,'Lampiran Site'!$B$3:$T$80,19,0) -> Go
A31: 37 | B31: Surabaya Gubeng;163135126 | C31: Surabaya Gubeng | D31: -7.26439 | E31: 112.75255 | F31: 163135126 | G31: -7.27344 | H31: 112.757 | I31: SURABAYA GUBENG - NGAGEL 2 | J31: Star | K31: 1676 | L31: SURABAYA GUBENG | M31: NGAGEL 2 | N31: KAI | O31: Station | P31: Direct to Station | R31: Jawa Timur | S31: KOTA SURABAYA | U31: =VLOOKUP(F31,'Lampiran Site'!$B$3:$T$80,19,0) -> Go
A32: 38 | B32: Surabaya Gubeng;T000041 | C32: Surabaya Gubeng | D32: -7.26439 | E32: 112.75255 | F32: T000041 | G32: -7.26815 | H32: 112.76104 | I32: SURABAYA GUBENG - NGAGEL 3 | J32: Star | K32: 1860 | L32: SURABAYA GUBENG | M32: NGAGEL 3 | N32: KAI | O32: Station | P32: Direct to Station | R32: Jawa Timur | S32: KOTA SURABAYA | U32: =VLOOKUP(F32,'Lampiran Site'!$B$3:$T$80,19,0) -> Go
A33: 40 | B33: Margorejo;T000512 | C33: Margorejo | D33: -7.316243 | E33: 112.73411 | F33: T000512 | G33: -7.31856 | H33: 112.74363 | I33: MARGOREJO - KERTOMENANGGAL 1 | J33: Star | K33: 1394 | L33: MARGOREJO | M33: KERTOMENANGGAL 1 | N33: KAI | O33: Station | P33: Direct to Station | R33: Jawa Timur | S33: KOTA SURABAYA | U33: =VLOOKUP(F33,'Lampiran Site'!$B$3:$T$80,19,0) -> Go
A34: 42 | B34: 1647052007;Sawotratap | C34: 1647052007 | D34: -7.36763 | E34: 112.73315 | F34: Sawotratap | G34: -7.367798 | H34: 112.72943 | I34: WARU - SAWOTRATAP 2 | J34: Star | K34: 606 | L34: WARU | M34: SAWOTRATAP 2 | N34: KAI | O34: Direct to Station | P34: Sation | R34: Jawa Timur | S34: KAB. SIDOARJO | U34: =VLOOKUP(C34,'Lampiran Site'!$B$3:$T$80,19,0) -> Go
A35: 43 | B35: Waru;161876109 | C35: Waru | D35: -7.35115 | E35: 112.7293 | F35: 161876109 | G35: -7.35092 | H35: 112.73339 | I35: WARU - SAWOTRATAP 3 | J35: Star | K35: 564 | L35: WARU | M35: SAWOTRATAP 3 | N35: KAI | O35: Station | P35: Direct to Station | R35: Jawa Timur | S35: KAB. SIDOARJO | U35: =VLOOKUP(F35,'Lampiran Site'!$B$3:$T$80,19,0) -> Go
A36: 44 | B36: 161420110;Buduran | C36: 161420110 | D36: -7.43213 | E36: 112.72768 | F36: Buduran | G36: -7.428294 | H36: 112.72282 | I36: GEDANGAN - BUDURAN 3 | J36: Star | K36: 1201 | L36: GEDANGAN | M36: BUDURAN 3 | N36: KAI | O36: Direct to Station | P36: Sation | R36: Jawa Timur | S36: KAB. SIDOARJO | U36: =VLOOKUP(C36,'Lampiran Site'!$B$3:$T$80,19,0) -> Go
A37: 45 | B37: Pagerwojo;163181126 | C37: Pagerwojo | D37: -7.442376 | E37: 112.71524 | F37: 163181126 | G37: -7.44211 | H37: 112.71442 | I37: PAGERWOJO - SIDOARJO 2 | J37: Star | K37: 102 | L37: PAGERWOJO | M37: SIDOARJO 2 | N37: KAI | O37: Station | P37: Direct to Station | R37: Jawa Timur | S37: KAB. SIDOARJO | U37: =VLOOKUP(F37,'Lampiran Site'!$B$3:$T$80,19,0) -> Go
A38: 46 | B38: 1649262007;Sidoarjo | C38: 1649262007 | D38: -7.44911 | E38: 112.71009 | F38: Sidoarjo | G38: -7.454206 | H38: 112.71315 | I38: PAGERWOJO - SIDOARJO 2 | J38: Star | K38: 1226 | L38: PAGERWOJO | M38: SIDOARJO 2 | N38: KAI | O38: Direct to Station | P38: Sation | R38: Jawa Timur | S38: KAB. SIDOARJO | U38: =VLOOKUP(C38,'Lampiran Site'!$B$3:$T$80,19,0) -> Go
A39: 47 | B39: 1647062007;Gedangan | C39: 1647062007 | D39: -7.38745 | E39: 112.72716 | F39: Gedangan | G39: -7.389484 | H39: 112.72871 | I39: SEPANJANG - GEDANGAN 1 | J39: Star | K39: 520 | L39: SEPANJANG | M39: GEDANGAN 1 | N39: KAI | O39: Direct to Station | P39: Sation | R39: Jawa Timur | S39: KAB. SIDOARJO | U39: =VLOOKUP(C39,'Lampiran Site'!$B$3:$T$80,19,0) -> Go
A40: 48 | B40: Mojokerto;163157126 | C40: Mojokerto | D40: -7.472328 | E40: 112.43206 | F40: 163157126 | G40: -7.47632 | H40: 112.43198 | I40: MOJOKERTO - CURAHMALANG 1 | J40: Star | K40: 536 | L40: MOJOKERTO | M40: CURAHMALANG 1 | N40: KAI | O40: Station | P40: Direct to Station | R40: Jawa Timur | S40: KOTA MOJOKERTO | U40: =VLOOKUP(F40,'Lampiran Site'!$B$3:$T$80,19,0) -> Go
...
